<robot name = "linkage">
  <link name="world"/>

  <link name = "link A1">
    <inertial>
      <origin xyz = "0 0 0" />
      <mass value = "0.5" />
      <inertia ixx = "0.5" iyy = "0.5" izz = "0.5" 
ixy = "0" ixz = "0" iyz = "0" />
    </inertial>
    <visual>
      <origin xyz = "0 0 0" />
      <geometry>
        <box size = "0.5 0.5 0.05" />
      </geometry>
      <material name = "gray A">
        <color rgba = "0.1 0.1 0.1 1" />
      </material>
    </visual>
  </link>
  <link name = "link A2">

    <inertial>
      <origin xyz = "0 0 -0.05" />
      <mass value = "0.5" />
      <inertia ixx = "0.5" iyy = "0.5" izz = "0.5" 
ixy = "0" ixz = "0" iyz = "0" />
    </inertial>
    <visual>
      <origin xyz = "0 0 0" />
      <geometry>
        <box size = "0.5 0.5 0.05" />
      </geometry>
      <material name = "gray A">
        <color rgba = "0.1 0.1 0.1 1" />
      </material>
    </visual>
  </link>

  <link name = "link B">
    <inertial>
      <origin xyz = "0 0 -0.5" />
      <mass value = "0.5" />
      <inertia ixx = "0.5" iyy = "0.5" izz = "0.5" 
  ixy = "0" ixz = "0" iyz = "0" />
    </inertial>
    <visual>
      <origin xyz = "0 0 -0.5" />
      <geometry>
        <cylinder radius = "0.05" length = "1"  />
      </geometry>
      <material name = "gray B">
        <color rgba = "0.3 0.3 0.3 1" />
      </material>
    </visual>
  </link>

  <link name = "link C">
    <inertial>
      <origin xyz = "0 0 -0.5" />
      <mass value = "0.5" />
      <inertia ixx = "0.5" iyy = "0.5" izz = "0.5" 
  ixy = "0" ixz = "0" iyz = "0" />
    </inertial>
    <visual>
      <origin xyz = "0 0 -0.5" />
      <geometry>
        <cylinder radius = "0.05" length = "1"  />
      </geometry>
      <material name = "gray C">
        <color rgba = "0.5 0.5 0.5 1" />
      </material>
    </visual>
  </link>

  <link name = "link D">
    <inertial>
      <origin xyz = "0 0 0" />
      <mass value = "0.5" />
      <inertia ixx = "0.5" iyy = "0.5" izz = "0.5" 
ixy = "0" ixz = "0" iyz = "0" />
    </inertial>
    <visual>
      <origin xyz = "0 0 -0.6" />
      <geometry>
        <box size = "0.1 0.1 0.1" />
      </geometry>
      <material name = "gray A">
        <color rgba = "0.1 0.1 0.1 1" />
      </material>
    </visual>
  </link>

  <joint name="fixed" type="fixed">
      <parent link="world"/>
      <child link="link A1"/>
  </joint>
  <joint name = "joint A" type = "continuous">
    <parent link = "link A1" />
    <child link = "link A2" />
    <origin xyz = "0 0 -0.05" />
    <axis xyz = "0 0 1" />
  </joint>
   <joint name = "joint B" type = "continuous">
    <parent link = "link A2" />
    <child link = "link B" />
    <origin xyz = "0 0 -0.05" />
    <axis xyz = "1 0 0" />
  </joint>
  <joint name = "joint C" type = "continuous">
    <parent link = "link B" />
    <child link = "link C" />
    <origin xyz = "0 0 -1" />
    <axis xyz = "1 0 0" />
    <dynamics damping ="0.2" />
  </joint>
  <joint name = "joint D" type = "continuous">
    <parent link = "link C" />
    <child link = "link D" />
    <origin xyz = "0 0 -0.45" />
    <axis xyz = "1 0 0" />
    <dynamics damping ="0.2" />
  </joint>
</robot>